Workbook
Name Ambusher: 'Troop Stats'!$E$21
Name BandsOfSteel: 'Troop Stats'!$E$16
Name BodyOfLightDamageTaken: 'Troop Stats'!$E$19
Name BodyOfLightDefense: 'Troop Stats'!$E$18
Name Charge: 'Troop Stats'!$E$20
Name CrystalGunpowder: 'Troop Stats'!$E$26
Name CrystalLance: 'Troop Stats'!$E$22
Name CrystalShield: 'Troop Stats'!$E$17
Name F9T11_InfantryAttack: 'Troop Stats'!$B$2
Name F9T11_InfantryDefense: 'Troop Stats'!$B$3
Name F9T11_InfantryHealth: 'Troop Stats'!$B$5
Name F9T11_InfantryLethality: 'Troop Stats'!$B$4
Name F9T11_LancerAttack: 'Troop Stats'!$C$2
Name F9T11_LancerDefense: 'Troop Stats'!$C$3
Name F9T11_LancerHealth: 'Troop Stats'!$C$5
Name F9T11_LancerLethality: 'Troop Stats'!$C$4
Name F9T11_MarksmanAttack: 'Troop Stats'!$D$2
Name F9T11_MarksmanDefense: 'Troop Stats'!$D$3
Name F9T11_MarksmanHealth: 'Troop Stats'!$D$5
Name F9T11_MarksmanLethality: 'Troop Stats'!$D$4
Name FlameCharge: 'Troop Stats'!$E$27
Name FlameCharge_Damage: 'Troop Stats'!$E$28
Name FoeInfantry_UnitHealth: Simulator_Main!$J$21
Name FoeLancer_UnitHealth: Simulator_Main!$K$21
Name FoeMarksman_UnitHealth: Simulator_Main!$L$21
Name HeroName: 'Hero Profile'!$B$8:$B$212
Name IncandescentField: 'Troop Stats'!$E$23
Name MasterBrawler: 'Troop Stats'!$E$15
Name MyInfantry_UnitHealth: Simulator_Main!$D$21
Name MyLancer_UnitHealth: Simulator_Main!$E$21
Name MyMarksman_UnitHealth: Simulator_Main!$F$21
Name RangedStrike: 'Troop Stats'!$E$24
Name ScoutedPosition: 'Current Stats - Enemy'!$M$2
Name selfScoutedPosition: 'Current Stats - Self'!$N$1
Name Volley: 'Troop Stats'!$E$25

Sheet MAIN PAGE
A1: Battle Formation Simulator
G2: Hypothetical Formula
A3: My role | B3: Garrison | G3: Troop Loss = | H3: Attack*lethality*(1+damage dealt buff)*(1+enemy damage taken buff) | M3: Enemy Role | N3: =IF(B3="Rally","Garrison","Rally") -> Rally
H4: (defense*health)/(troop type unit health)
A5: Total Troops | B5: 1644203 | M5: Total Troops | N5: 1644203
B6: 11
B7: Infantry | C7: Lancer | D7: Marksman | F7: Troops Survived | G7: =IF(F8<K8,"LOSS!", "WIN!") -> #VALUE! | K7: Troops Survived | N7: Infantry | O7: Lancer | P7: Marksman
A8: My formation | B8: 0.5 | C8: 0.1 | D8: =1-B8-C8 -> 0.4 | F8: =SUM(B31:D31) -> #VALUE! | K8: =SUM(N31:P31) -> #VALUE! | M8: Enemy's Formation | N8: 0.5 | O8: 0 | P8: =1-N8-O8 -> 0.5
A10: Hero Gears | B10: Infantry | C10: Lancer | D10: Marksman | G10: My item buffs | J10: Enemy item buffs | M10: Hero Gears | N10: Infantry | O10: Lancer | P10: Marksman
A11: Attack | B11: 1 | C11: 1 | D11: 1 | G11: 0.2 | H11: My | I11: Attack | J11: 0.2 | M11: Attack | N11: 1 | O11: 1 | P11: 1
A12: Defense | B12: 1 | C12: 1 | D12: 1 | G12: 0.2 | H12: My | I12: Defense | J12: 0.2 | M12: Defense | N12: 1 | O12: 1 | P12: 1
A13: Lethality | B13: 1 | C13: 1 | D13: 1 | G13: 0.2 | H13: My | I13: Lethality | J13: 0.2 | M13: Lethality | N13: 1 | O13: 1 | P13: 1
A14: Heatlh | B14: 1 | C14: 1 | D14: 1 | G14: 0.2 | H14: My | I14: Health | J14: 0.2 | M14: Heatlh | N14: 1 | O14: 1 | P14: 1
G15: -0.2 | H15: Enemy | I15: Attack | J15: -0.2
G16: -0.2 | H16: Enemy | I16: Defense | J16: -0.2
C18: =B3 & " Lead Hero" -> Garrison Lead Hero | G18: My pet buffs | J18: Enemy pet buffs | N18: =N3 & " Lead Hero" -> Rally Lead Hero
C19: Hervor | D19: {=INDEX('Hero Profile'!$A:$A,MATCH(C19,'Hero Profile'!$B:$B,FALSE))} -> 0 | G19: 0.1 | H19: My | I19: Attack | J19: 0.1 | N19: Hervor | O19: {=INDEX('Hero Profile'!$A:$A,MATCH(N19,'Hero Profile'!$B:$B,FALSE))} -> 0
C21: Lloyd | D21: {=INDEX('Hero Profile'!$A:$A,MATCH(C21,'Hero Profile'!$B:$B,FALSE))} -> 0 | G21: 0.1 | H21: My | I21: Defense | J21: 0.1 | N21: Karol | O21: {=INDEX('Hero Profile'!$A:$A,MATCH(N21,'Hero Profile'!$B:$B,FALSE))} -> 0
C22: Ligeia | D22: {=INDEX('Hero Profile'!$A:$A,MATCH(C22,'Hero Profile'!$B:$B,FALSE))} -> 0 | G22: 0.1 | H22: My | I22: Lethality | J22: 0.1 | N22: Rufus | O22: {=INDEX('Hero Profile'!$A:$A,MATCH(N22,'Hero Profile'!$B:$B,FALSE))} -> 0
G23: 0.1 | H23: My | I23: Health | J23: 0.1
C24: Joiners | G24: -0.05 | H24: Enemy | I24: Lethality | J24: -0.05 | N24: Joiners
C25: Bradley | D25: {=INDEX('Hero Profile'!$A:$A,MATCH(C25,'Hero Profile'!$B:$B,FALSE))} -> 0 | G25: -0.05 | H25: Enemy | I25: Health | J25: -0.05 | N25: Nora | O25: {=INDEX('Hero Profile'!$A:$A,MATCH(N25,'Hero Profile'!$B:$B,FALSE))} -> 0
C26: Gregory | D26: {=INDEX('Hero Profile'!$A:$A,MATCH(C26,'Hero Profile'!$B:$B,FALSE))} -> 0 | N26: Nora | O26: {=INDEX('Hero Profile'!$A:$A,MATCH(N26,'Hero Profile'!$B:$B,FALSE))} -> 0
C27: Patrick | D27: {=INDEX('Hero Profile'!$A:$A,MATCH(C27,'Hero Profile'!$B:$B,FALSE))} -> 0 | G27: My base stats | J27: Enemy base stats | N27: Nora | O27: {=INDEX('Hero Profile'!$A:$A,MATCH(N27,'Hero Profile'!$B:$B,FALSE))} -> 0
C28: Gatot | D28: {=INDEX('Hero Profile'!$A:$A,MATCH(C28,'Hero Profile'!$B:$B,FALSE))} -> 0 | F28: =G28-J28 -> 0 | G28: ='Current Stats - Self'!H4 -> 10.96 | H28: ='Current Stats - Self'!A4 -> Infantry | I28: ='Current Stats - Self'!B4 -> Attack | J28: ='Current Stats - Enemy'!H4 -> 10.96 | N28: Nora | O28: {=INDEX('Hero Profile'!$A:$A,MATCH(N28,'Hero Profile'!$B:$B,FALSE))} -> 0
F29: =G29-J29 -> 0 | G29: ='Current Stats - Self'!H5 -> 11.195 | H29: ='Current Stats - Self'!A5 -> Infantry | I29: ='Current Stats - Self'!B5 -> Defense | J29: ='Current Stats - Enemy'!H5 -> 11.195
B30: Infantry | C30: Lancer | D30: Marksman | F30: =G30-J30 -> 0 | G30: ='Current Stats - Self'!H6 -> 11.566 | H30: ='Current Stats - Self'!A6 -> Infantry | I30: ='Current Stats - Self'!B6 -> Lethality | J30: ='Current Stats - Enemy'!H6 -> 11.566 | N30: Infantry | O30: Lancer | P30: Marksman
A31: Troops Survived | B31: =Simulator_Main!D23 -> #VALUE! | C31: =Simulator_Main!E23 -> #VALUE! | D31: =Simulator_Main!F23 -> #VALUE! | F31: =G31-J31 -> 0 | G31: ='Current Stats - Self'!H7 -> 11.486 | H31: ='Current Stats - Self'!A7 -> Infantry | I31: ='Current Stats - Self'!B7 -> Health | J31: ='Current Stats - Enemy'!H7 -> 11.486 | M31: Troops Survived | N31: =Simulator_Main!J23 -> #VALUE! | O31: =Simulator_Main!K23 -> 0 | P31: =Simulator_Main!L23 -> #VALUE!
F32: =G32-J32 -> 0 | G32: ='Current Stats - Self'!H8 -> 10.96 | H32: ='Current Stats - Self'!A8 -> Lancer | I32: ='Current Stats - Self'!B8 -> Attack | J32: ='Current Stats - Enemy'!H8 -> 10.96
A33: Me vs Enemy | B33: Infantry | C33: Lancer | D33: Marksman | F33: =G33-J33 -> 0 | G33: ='Current Stats - Self'!H9 -> 11.195 | H33: ='Current Stats - Self'!A9 -> Lancer | I33: ='Current Stats - Self'!B9 -> Defense | J33: ='Current Stats - Enemy'!H9 -> 11.195
A34: Attack | B34: =G28-J33 -> -0.235 | C34: =G32-J37 -> -0.235 | D34: =G36-J29 -> -0.235 | F34: =G34-J34 -> 0 | G34: ='Current Stats - Self'!H10 -> 11.58 | H34: ='Current Stats - Self'!A10 -> Lancer | I34: ='Current Stats - Self'!B10 -> Lethality | J34: ='Current Stats - Enemy'!H10 -> 11.58
A35: Defense | B35: =G29-J36 -> 0.235 | C35: =G33-J28 -> 0.235 | D35: =G37-J32 -> 0.235 | F35: =G35-J35 -> 0 | G35: ='Current Stats - Self'!H11 -> 11.479 | H35: ='Current Stats - Self'!A11 -> Lancer | I35: ='Current Stats - Self'!B11 -> Health | J35: ='Current Stats - Enemy'!H11 -> 11.479
A36: Lethality | B36: =G30-J35 -> 0.087 | C36: =G34-J39 -> 0.312 | D36: =G38-J31 -> -0.131 | F36: =G36-J36 -> 0 | G36: ='Current Stats - Self'!H12 -> 10.96 | H36: ='Current Stats - Self'!A12 -> Marksman | I36: ='Current Stats - Self'!B12 -> Attack | J36: ='Current Stats - Enemy'!H12 -> 10.96
A37: Heatlh | B37: =G31-J38 -> 0.131 | C37: =G35-J30 -> -0.087 | D37: =G39-J34 -> -0.312 | F37: =G37-J37 -> 0 | G37: ='Current Stats - Self'!H13 -> 11.195 | H37: ='Current Stats - Self'!A13 -> Marksman | I37: ='Current Stats - Self'!B13 -> Defense | J37: ='Current Stats - Enemy'!H13 -> 11.195
F38: =G38-J38 -> 0 | G38: ='Current Stats - Self'!H14 -> 11.355 | H38: ='Current Stats - Self'!A14 -> Marksman | I38: ='Current Stats - Self'!B14 -> Lethality | J38: ='Current Stats - Enemy'!H14 -> 11.355
F39: =G39-J39 -> 0 | G39: ='Current Stats - Self'!H15 -> 11.268 | H39: ='Current Stats - Self'!A15 -> Marksman | I39: ='Current Stats - Self'!B15 -> Health | J39: ='Current Stats - Enemy'!H15 -> 11.268

Sheet Combo Tester
B1: Battle Formation Simulator | E1: My role | F1: Garrison | I1: Enemy Role | J1: =IF(F1="Rally","Garrison","Rally") -> Rally
B4: Total Troops | C4: 1644203 | I4: Total Troops | J4: 1644203
C5: 11
C6: Infantry | D6: Lancer | E6: Marksman | J6: Infantry | K6: Lancer | L6: Marksman
B7: My formation | C7: 0.6 | D7: 0.4 | E7: =1-C7-D7 -> 0 | I7: Enemy | J7: 0.6 | K7: 0.3 | L7: =1-K7-J7 -> 0.1
B8: Number | C8: =C7*$C$4 -> 986521.8 | D8: =D7*$C$4 -> 657681.2 | E8: =E7*$C$4 -> 0 | I8: Number | J8: =J7*$J$4 -> 986521.8 | K8: =K7*$J$4 -> 493260.9 | L8: =L7*$J$4 -> 164420.3
B11: Final Stats | C11: Infantry | D11: Lancer | E11: Marksman
B12: Attack | C12: 1 | D12: 1 | E12: 1
B13: Defense | C13: 1 | D13: 1 | E13: 1
B14: Lethality | C14: 1 | D14: 1 | E14: 1
B15: Heatlh | C15: 1 | D15: 1 | E15: 1
B18: Friend | I18: Opponent
B19: Gisela | C19: {=INDEX('Hero Profile'!$A:$A,MATCH(B19,'Hero Profile'!$B:$B,FALSE))} -> 0 | I19: Elif | J19: {=INDEX('Hero Profile'!$A:$A,MATCH(I19,'Hero Profile'!$B:$B,FALSE))} -> 0
B20: Flora | C20: {=INDEX('Hero Profile'!$A:$A,MATCH(B20,'Hero Profile'!$B:$B,FALSE))} -> 0 | I20: Dominic | J20: {=INDEX('Hero Profile'!$A:$A,MATCH(I20,'Hero Profile'!$B:$B,FALSE))} -> 0
B21: Bradley | C21: {=INDEX('Hero Profile'!$A:$A,MATCH(B21,'Hero Profile'!$B:$B,FALSE))} -> 0 | I21: Vulcanus | J21: {=INDEX('Hero Profile'!$A:$A,MATCH(I21,'Hero Profile'!$B:$B,FALSE))} -> 0
B23: Joiners | I23: Joiners
B24: Ling Xue | C24: {=INDEX('Hero Profile'!$A:$A,MATCH(B24,'Hero Profile'!$B:$B,FALSE))} -> 0 | I24: Jessie | J24: {=INDEX('Hero Profile'!$A:$A,MATCH(I24,'Hero Profile'!$B:$B,FALSE))} -> 0
B25: Gregory | C25: {=INDEX('Hero Profile'!$A:$A,MATCH(B25,'Hero Profile'!$B:$B,FALSE))} -> 0 | I25: Rufus | J25: {=INDEX('Hero Profile'!$A:$A,MATCH(I25,'Hero Profile'!$B:$B,FALSE))} -> 0
B26: Renee | C26: {=INDEX('Hero Profile'!$A:$A,MATCH(B26,'Hero Profile'!$B:$B,FALSE))} -> 0 | I26: Hendrik | J26: {=INDEX('Hero Profile'!$A:$A,MATCH(I26,'Hero Profile'!$B:$B,FALSE))} -> 0
B27: Gordon | C27: {=INDEX('Hero Profile'!$A:$A,MATCH(B27,'Hero Profile'!$B:$B,FALSE))} -> 0 | I27: Blanchette | J27: {=INDEX('Hero Profile'!$A:$A,MATCH(I27,'Hero Profile'!$B:$B,FALSE))} -> 0
H28: Score
G29: Normal Damage | H29: =(F37+F41)/(M38-M43) -> 0.8654315
G30: Skilled Damage | H30: =(F39+F42)/(M40-M44) -> 0.50099487
G31: Defense | H31: =(SUM(C38:E38)-SUM(C43:E43))/SUM(J37:L37,J41:L41) -> 0.71014064
G32: Health | H32: =(SUM(C40:E40)-SUM(C44:E44))/SUM(J39:L39,J42:L42) -> 0.98981274
B34: Aggregate Effects
C36: Infantry | D36: Lancer | E36: Marksman | F36: Total | J36: Infantry | K36: Lancer | L36: Marksman | M36: Total
B37: Attack | C37: =MAX(0,C62*C$8+C50) -> 23429893 | D37: =MAX(0,D62*D$8+D50) -> 23018842 | E37: =MAX(0,E62*E$8+E50) -> 0 | F37: =MAX(0,C37:E37) -> 23429893 | I37: Attack | J37: =MAX(0,J62*J$8+J50) -> 23992210 | K37: =MAX(0,K62*K$8+K50) -> 16573566 | L37: =MAX(0,L62*L$8+L50) -> 6617588.2 | M37: =MAX(0,J37:L37) -> 23992210
B38: Defense | C38: =MAX(0,C63*C$8+C51) -> 33477124 | D38: =MAX(0,D63*D$8+D51) -> 9490339.7 | E38: =MAX(0,E63*E$8+E51) -> 0 | F38: =MAX(0,C38:E38) -> 33477124 | I38: Defense | J38: =MAX(0,J63*J$8+J51) -> 37607033 | K38: =MAX(0,K63*K$8+K51) -> 10605109 | L38: =MAX(0,L63*L$8+L51) -> 0 | M38: =MAX(0,J38:L38) -> 37607033
B39: Lethality | C39: =MAX(0,C64*C$8+C52) -> 17757392 | D39: =MAX(0,D64*D$8+D52) -> 19664668 | E39: =MAX(0,E64*E$8+E52) -> 0 | F39: =MAX(0,C39:E39) -> 19664668 | I39: Lethality | J39: =MAX(0,J64*J$8+J52) -> 22196740 | K39: =MAX(0,K64*K$8+K52) -> 18435626 | L39: =MAX(0,L64*L$8+L52) -> 7005846.2 | M39: =MAX(0,J39:L39) -> 22196740
B40: Heatlh | C40: =MAX(0,C65*C$8+C53) -> 46411997 | D40: =MAX(0,D65*D$8+D53) -> 16111648 | E40: =MAX(0,E65*E$8+E53) -> 0 | F40: =MAX(0,C40:E40) -> 46411997 | I40: Heatlh | J40: =MAX(0,J65*J$8+J53) -> 41914845 | K40: =MAX(0,K65*K$8+K53) -> 10649503 | L40: =MAX(0,L65*L$8+L53) -> 3288406 | M40: =MAX(0,J40:L40) -> 41914845
B41: Normal Damage Dealt | C41: =C56 -> 0 | D41: =D56 -> 5754710.5 | E41: =E56 -> 0 | F41: =MAX(0,C41:E41) -> 5754710.5 | I41: Normal Damage Dealt | J41: =J56 -> 13495618 | K41: =K56 -> 7458104.8 | L41: =L56 -> 3551478.5 | M41: =MAX(0,J41:L41) -> 13495618
B42: Skill Damage Dealt | C42: =C57 -> 0 | D42: =D57 -> 0 | E42: =E57 -> 0 | F42: =MAX(0,C42:E42) -> 0 | I42: Skill Damage Dealt | J42: =J57 -> 5549185.1 | K42: =K57 -> 4007744.8 | L42: =L57 -> 1387296.3 | M42: =MAX(0,J42:L42) -> 5549185.1
B43: Normal Damage Taken | C43: =C58 -> -7941500.5 | D43: =D58 -> 0 | E43: =E58 -> 0 | F43: =MAX(0,C43:E43) -> 0 | I43: Normal Damage Taken | J43: =J58 -> 3452826.3 | K43: =K58 -> 3884429.6 | L43: =L58 -> -647404.93 | M43: =MAX(0,J43:L43) -> 3884429.6
B44: Skill Damage Taken | C44: =C59 -> 0 | D44: =D59 -> 4538000.3 | E44: =E59 -> 0 | F44: =MAX(0,C44:E44) -> 4538000.3 | I44: Skill Damage Taken | J44: =J59 -> 2663608.9 | K44: =K59 -> 0 | L44: =L59 -> -493260.9 | M44: =MAX(0,J44:L44) -> 2663608.9
B47: Troop Effects
B49: Troop Type Modifers | C49: Infantry | D49: Lancer | E49: Marksman | I49: Modifers | J49: Infantry | K49: Lancer | L49: Marksman
B50: Attack Modifier | E50: =E62*10%*E8+30%*(6%*E62*E8) -> 0 | I50: Attack Modifier | J50: =J62*10%*D8 -> 1499513.1 | K50: =E8*10%*K62+20%*L62*E8 -> 0 | L50: =L62*10%*L8+30%*(6%*L62*L8) -> 698457.43
B51: Defense Modifier | C51: =K8*C63*10%+37.5%*6%*C63*C8-L62*10%*L8 -> 1711122.1 | D51: =-J62*10%*J8 -> -2249269.7 | E51: =-K8*10%*K62-20%*L62*K8 -> -5208835.1 | I51: Defense Modifier | J51: =D8*J63*10%+37.5%*6%*J63*J8-E62*10%*E8 -> 3078770.1 | K51: =-C62*10%*C8 -> -2342989.3 | L51: =-D8*10%*D62-20%*D62*D8 -> -6905652.6
B52: Lethality Modifier | D52: =15%*D64*D8 -> 2564956.7 | E52: =30%*(50%*E64*E8+37.5%*E64*E8) -> 0 | I52: Lethality Modifier | K52: =15%*K64*K8 -> 2404646.9 | L52: =30%*(50%*L64*L8+37.5%*L64*L8) -> 1456661.1
...

Sheet Experiments
B1: Battle Formation Simulator | E1: My role | F1: Garrison | I1: Enemy Role | J1: =IF(F1="Rally","Garrison","Rally") -> Rally
B4: Total Troops | C4: 1644203 | I4: Total Troops | J4: 1644203
C5: 11
C6: Infantry | D6: Lancer | E6: Marksman | J6: Infantry | K6: Lancer | L6: Marksman
B7: My formation | C7: 0.6 | D7: 0.4 | E7: =1-C7-D7 -> 0 | I7: Enemy | J7: 0.6 | K7: 0.3 | L7: =1-K7-J7 -> 0.1
B8: Number | C8: =C7*$C$4 -> 986521.8 | D8: =D7*$C$4 -> 657681.2 | E8: =E7*$C$4 -> 0 | I8: Number | J8: =J7*$J$4 -> 986521.8 | K8: =K7*$J$4 -> 493260.9 | L8: =L7*$J$4 -> 164420.3
B11: Final Stats | C11: Infantry | D11: Lancer | E11: Marksman
B12: Attack | C12: 1 | D12: 1 | E12: 1
B13: Defense | C13: 1 | D13: 1 | E13: 1
B14: Lethality | C14: 1 | D14: 1 | E14: 1
B15: Heatlh | C15: 1 | D15: 1 | E15: 1
B18: Friend | I18: Opponent
B19: Gisela | C19: {=INDEX('Hero Profile'!$A:$A,MATCH(B19,'Hero Profile'!$B:$B,FALSE))} -> 0 | I19: Gisela | J19: {=INDEX('Hero Profile'!$A:$A,MATCH(I19,'Hero Profile'!$B:$B,FALSE))} -> 0
B20: Flora | C20: {=INDEX('Hero Profile'!$A:$A,MATCH(B20,'Hero Profile'!$B:$B,FALSE))} -> 0 | I20: Flora | J20: {=INDEX('Hero Profile'!$A:$A,MATCH(I20,'Hero Profile'!$B:$B,FALSE))} -> 0
B21: Vulcanus | C21: {=INDEX('Hero Profile'!$A:$A,MATCH(B21,'Hero Profile'!$B:$B,FALSE))} -> 0 | I21: Vulcanus | J21: {=INDEX('Hero Profile'!$A:$A,MATCH(I21,'Hero Profile'!$B:$B,FALSE))} -> 0
B23: Joiners | I23: Joiners
B24: Ling Xue | C24: {=INDEX('Hero Profile'!$A:$A,MATCH(B24,'Hero Profile'!$B:$B,FALSE))} -> 0 | I24: Jessie | J24: {=INDEX('Hero Profile'!$A:$A,MATCH(I24,'Hero Profile'!$B:$B,FALSE))} -> 0
B25: Karol | C25: {=INDEX('Hero Profile'!$A:$A,MATCH(B25,'Hero Profile'!$B:$B,FALSE))} -> 0 | I25: Rufus | J25: {=INDEX('Hero Profile'!$A:$A,MATCH(I25,'Hero Profile'!$B:$B,FALSE))} -> 0
B26: Renee | C26: {=INDEX('Hero Profile'!$A:$A,MATCH(B26,'Hero Profile'!$B:$B,FALSE))} -> 0 | I26: Hendrik | J26: {=INDEX('Hero Profile'!$A:$A,MATCH(I26,'Hero Profile'!$B:$B,FALSE))} -> 0
B27: Gordon | C27: {=INDEX('Hero Profile'!$A:$A,MATCH(B27,'Hero Profile'!$B:$B,FALSE))} -> 0 | I27: Blanchette | J27: {=INDEX('Hero Profile'!$A:$A,MATCH(I27,'Hero Profile'!$B:$B,FALSE))} -> 0
H28: Score
G29: Normal Damage | H29: =(F37+F41)/(M38-M43) -> 0.56710696
G30: Skilled Damage | H30: =(F39+F42)/(M40-M44) -> 0.42832841
G31: Defense | H31: =(SUM(C38:E38)-SUM(C43:E43))/SUM(J37:L37,J41:L41) -> 1.0398215
G32: Health | H32: =(SUM(C40:E40)-SUM(C44:E44))/SUM(J39:L39,J42:L42) -> 1.2234943
B34: Aggregate Effects
C36: Infantry | D36: Lancer | E36: Marksman | F36: Total | J36: Infantry | K36: Lancer | L36: Marksman | M36: Total
B37: Attack | C37: =MAX(0,C62*C$8+C50) -> 17806718 | D37: =MAX(0,D62*D$8+D50) -> 17494320 | E37: =MAX(0,E62*E$8+E50) -> 0 | F37: =MAX(0,C37:E37) -> 17806718 | I37: Attack | J37: =MAX(0,J62*J$8+J50) -> 19993508 | K37: =MAX(0,K62*K$8+K50) -> 13811305 | L37: =MAX(0,L62*L$8+L50) -> 5514656.9 | M37: =MAX(0,J37:L37) -> 19993508
B38: Defense | C38: =MAX(0,C63*C$8+C51) -> 30613251 | D38: =MAX(0,D63*D$8+D51) -> 8484087.5 | E38: =MAX(0,E63*E$8+E51) -> 0 | F38: =MAX(0,C38:E38) -> 30613251 | I38: Defense | J38: =MAX(0,J63*J$8+J51) -> 39111314 | K38: =MAX(0,K63*K$8+K51) -> 8577807.1 | L38: =MAX(0,L63*L$8+L51) -> 0 | M38: =MAX(0,J38:L38) -> 39111314
B39: Lethality | C39: =MAX(0,C64*C$8+C52) -> 17757392 | D39: =MAX(0,D64*D$8+D52) -> 19664668 | E39: =MAX(0,E64*E$8+E52) -> 0 | F39: =MAX(0,C39:E39) -> 19664668 | I39: Lethality | J39: =MAX(0,J64*J$8+J52) -> 22196740 | K39: =MAX(0,K64*K$8+K52) -> 18435626 | L39: =MAX(0,L64*L$8+L52) -> 7005846.2 | M39: =MAX(0,J39:L39) -> 22196740
B40: Heatlh | C40: =MAX(0,C65*C$8+C53) -> 46411997 | D40: =MAX(0,D65*D$8+D53) -> 16111648 | E40: =MAX(0,E65*E$8+E53) -> 0 | F40: =MAX(0,C40:E40) -> 46411997 | I40: Heatlh | J40: =MAX(0,J65*J$8+J53) -> 45910258 | K40: =MAX(0,K65*K$8+K53) -> 12129286 | L40: =MAX(0,L65*L$8+L53) -> 3781666.9 | M40: =MAX(0,J40:L40) -> 45910258
B41: Normal Damage Dealt | C41: =C56 -> 0 | D41: =D56 -> 4373580 | E41: =E56 -> 0 | F41: =MAX(0,C41:E41) -> 4373580 | I41: Normal Damage Dealt | J41: =J56 -> 4685978.5 | K41: =K56 -> 6905652.6 | L41: =L56 -> 1233152.2 | M41: =MAX(0,J41:L41) -> 6905652.6
B42: Skill Damage Dealt | C42: =C57 -> 0 | D42: =D57 -> 0 | E42: =E57 -> 0 | F42: =MAX(0,C42:E42) -> 0 | I42: Skill Damage Dealt | J42: =J57 -> 5549185.1 | K42: =K57 -> 4007744.8 | L42: =L57 -> 1387296.3 | M42: =MAX(0,J42:L42) -> 5549185.1
B43: Normal Damage Taken | C43: =C58 -> -13051683 | D43: =D58 -> -2071695.8 | E43: =E58 -> 0 | F43: =MAX(0,C43:E43) -> 0 | I43: Normal Damage Taken | J43: =J58 -> -8977348.4 | K43: =K58 -> 0 | L43: =L58 -> 0 | M43: =MAX(0,J43:L43) -> 0
B44: Skill Damage Taken | C44: =C59 -> -6126300.4 | D44: =D59 -> -3025333.5 | E44: =E59 -> 0 | F44: =MAX(0,C44:E44) -> 0 | I44: Skill Damage Taken | J44: =J59 -> 0 | K44: =K59 -> 0 | L44: =L59 -> 0 | M44: =MAX(0,J44:L44) -> 0
B47: Troop Effects
B49: Troop Type Modifers | C49: Infantry | D49: Lancer | E49: Marksman | I49: Modifers | J49: Infantry | K49: Lancer | L49: Marksman
B50: Attack Modifier | E50: =E62*10%*E8+30%*(6%*E62*E8) -> 0 | I50: Attack Modifier | J50: =J62*10%*D8 -> 1249594.3 | K50: =E8*10%*K62+20%*L62*E8 -> 0 | L50: =L62*10%*L8+30%*(6%*L62*L8) -> 582047.86
B51: Defense Modifier | C51: =K8*C63*10%+37.5%*6%*C63*C8-L62*10%*L8 -> 1609510.3 | D51: =-J62*10%*J8 -> -1874391.4 | E51: =-K8*10%*K62-20%*L62*K8 -> -4340695.9 | I51: Defense Modifier | J51: =D8*J63*10%+37.5%*6%*J63*J8-E62*10%*E8 -> 3201920.9 | K51: =-C62*10%*C8 -> -1780671.8 | L51: =-D8*10%*D62-20%*D62*D8 -> -5248296
B52: Lethality Modifier | D52: =15%*D64*D8 -> 2564956.7 | E52: =30%*(50%*E64*E8+37.5%*E64*E8) -> 0 | I52: Lethality Modifier | K52: =15%*K64*K8 -> 2404646.9 | L52: =30%*(50%*L64*L8+37.5%*L64*L8) -> 1456661.1
...

Sheet Current Stats - Self
A1: My Base Stats Calculator | M1: Combat Position | N1: Garrison
C2: Input
C3: Scouted Stats | D3: Heroes Effect | E3: Gear | F3: Gear Fudge | G3: Buffs Applied | H3: Base Stats | J3: Mati's Base Stats As At 14-Jun-25 | K3: Smarty's Base Stats | L3: Growth Since | O3: Greg Full | Q3: Magnus Full | T3: Magnus Naked | W3: Gatot Full | Z3: Gatot Naked | AB3: Gen 10 Full | AC3: Gen 10 Naked
A4: Infantry | B4: Attack | C4: =(H4+D4+E4*F4)*(1+G4)+G4 -> 29.78573 | D4: =SUMIFS('Hero Stats'!D:D,'Hero Stats'!A:A,$A$19,'Hero Stats'!B:B,A4,'Hero Stats'!C:C,B4) +SUMIFS('Hero Stats'!D:D,'Hero Stats'!A:A,$A$20,'Hero Stats'!B:B,A4,'Hero Stats'!C:C,B4) +SUMIFS('Hero Stats'!D:D,'Hero Stats'!A:A,$A$21,'Hero Stats'!B:B,A4,'Hero Stats'!C:C,B4) -> 12.8102 | E4: 2 | F4: 1 | G4: =C25 -> 0.15 | H4: 10.96 | J4: 10.3094 | K4: 10.36 | L4: =H4-K4 -> 0.6 | O4: 22.239 | P4: =O4-C4 -> -7.54673 | Q4: 21.687 | R4: =Q4-O4 -> -0.552 | T4: 19.687 | U4: =T4-O4 -> -2.552 | W4: 20.086 | X4: =W4-Q4 -> -1.601 | Z4: 18.086 | AA4: =Z4-C4 -> -11.69973 | AB4: 23.389 | AC4: 21.389 | AD4: =AC4-AB4 -> -2
A5: Infantry | B5: Defense | C5: =(H5+D5+E5*F5)*(1+G5)+G5 -> 26.0052 | D5: =SUMIFS('Hero Stats'!D:D,'Hero Stats'!A:A,$A$19,'Hero Stats'!B:B,A5,'Hero Stats'!C:C,B5) +SUMIFS('Hero Stats'!D:D,'Hero Stats'!A:A,$A$20,'Hero Stats'!B:B,A5,'Hero Stats'!C:C,B5) +SUMIFS('Hero Stats'!D:D,'Hero Stats'!A:A,$A$21,'Hero Stats'!B:B,A5,'Hero Stats'!C:C,B5) -> 12.8102 | E5: 2 | F5: 1 | G5: =C26 -> 0 | H5: 11.195 | J5: 10.6344 | K5: 10.635 | L5: =H5-K5 -> 0.56 | O5: 23.514 | P5: =O5-C5 -> -2.4912 | Q5: 21.912 | R5: =Q5-O5 -> -1.602 | T5: 19.912 | U5: =T5-O5 -> -3.602 | W5: 20.311 | X5: =W5-Q5 -> -1.601 | Z5: 18.311 | AA5: =Z5-C5 -> -7.6942 | AB5: 23.614 | AC5: 21.614 | AD5: =AC5-AB5 -> -2
A6: Infantry | B6: Lethality | C6: =(H6+D6+E6*F6)*(1+G6)+G6 -> 20.796 | D6: =SUMIFS('Hero Stats'!D:D,'Hero Stats'!A:A,$A$19,'Hero Stats'!B:B,A6,'Hero Stats'!C:C,B6) +SUMIFS('Hero Stats'!D:D,'Hero Stats'!A:A,$A$20,'Hero Stats'!B:B,A6,'Hero Stats'!C:C,B6) +SUMIFS('Hero Stats'!D:D,'Hero Stats'!A:A,$A$21,'Hero Stats'!B:B,A6,'Hero Stats'!C:C,B6) -> 3.23 | E6: 6 | F6: 1 | G6: =C27 -> 0 | H6: 11.566 | J6: 10.167609 | K6: 10.6 | L6: =H6-K6 -> 0.966 | O6: 19.275 | P6: =O6-C6 -> -1.521 | Q6: 18.92 | R6: =Q6-O6 -> -0.355 | T6: 12.92 | U6: =T6-O6 -> -6.355 | W6: 18.53 | X6: =W6-Q6 -> -0.39 | Z6: 12.53 | AA6: =Z6-C6 -> -8.266 | AB6: 19.375 | AC6: 13.375 | AD6: =AC6-AB6 -> -6
A7: Infantry | B7: Health | C7: =(H7+D7+E7*F7)*(1+G7)+G7 -> 23.9734 | D7: =SUMIFS('Hero Stats'!D:D,'Hero Stats'!A:A,$A$19,'Hero Stats'!B:B,A7,'Hero Stats'!C:C,B7) +SUMIFS('Hero Stats'!D:D,'Hero Stats'!A:A,$A$20,'Hero Stats'!B:B,A7,'Hero Stats'!C:C,B7) +SUMIFS('Hero Stats'!D:D,'Hero Stats'!A:A,$A$21,'Hero Stats'!B:B,A7,'Hero Stats'!C:C,B7) -> 3.23 | E7: 6 | F7: 1 | G7: =C28 -> 0.15 | H7: 11.486 | J7: 10.101 | K7: 10.558 | L7: =H7-K7 -> 0.928 | O7: 19.233 | P7: =O7-C7 -> -4.7404 | Q7: 18.878 | R7: =Q7-O7 -> -0.355 | T7: 12.878 | U7: =T7-O7 -> -6.355 | W7: 18.488 | X7: =W7-Q7 -> -0.39 | Z7: 12.488 | AA7: =Z7-C7 -> -11.4854 | AB7: 19.333 | AC7: 13.333 | AD7: =AC7-AB7 -> -6
A8: Lancer | B8: Attack | C8: =(H8+D8+E8*F8)*(1+G8)+G8 -> 29.78573 | D8: =SUMIFS('Hero Stats'!D:D,'Hero Stats'!A:A,$A$19,'Hero Stats'!B:B,A8,'Hero Stats'!C:C,B8) +SUMIFS('Hero Stats'!D:D,'Hero Stats'!A:A,$A$20,'Hero Stats'!B:B,A8,'Hero Stats'!C:C,B8) +SUMIFS('Hero Stats'!D:D,'Hero Stats'!A:A,$A$21,'Hero Stats'!B:B,A8,'Hero Stats'!C:C,B8) -> 12.8102 | E8: 2 | F8: 1 | G8: =C29 -> 0.15 | H8: 10.96 | J8: 10.2594 | K8: 10.32 | L8: =H8-K8 -> 0.64 | O8: 23.199 | P8: =O8-C8 -> -6.58673 | Q8: 23.349 | R8: =Q8-O8 -> 0.15 | T8: 23.349 | U8: =T8-O8 -> 0.15 | W8: 23.349 | X8: =W8-Q8 -> 0 | Z8: 23.349 | AA8: =Z8-C8 -> -6.43673 | AB8: 23.349 | AC8: 21.349 | AD8: =AC8-AB8 -> -2
A9: Lancer | B9: Defense | C9: =(H9+D9+E9*F9)*(1+G9)+G9 -> 26.0052 | D9: =SUMIFS('Hero Stats'!D:D,'Hero Stats'!A:A,$A$19,'Hero Stats'!B:B,A9,'Hero Stats'!C:C,B9) +SUMIFS('Hero Stats'!D:D,'Hero Stats'!A:A,$A$20,'Hero Stats'!B:B,A9,'Hero Stats'!C:C,B9) +SUMIFS('Hero Stats'!D:D,'Hero Stats'!A:A,$A$21,'Hero Stats'!B:B,A9,'Hero Stats'!C:C,B9) -> 12.8102 | E9: 2 | F9: 1 | G9: =C30 -> 0 | H9: 11.195 | J9: 10.6144 | K9: 10.615 | L9: =H9-K9 -> 0.58 | O9: 23.494 | P9: =O9-C9 -> -2.5112 | Q9: 23.594 | R9: =Q9-O9 -> 0.1 | T9: 23.594 | U9: =T9-O9 -> 0.1 | W9: 23.594 | X9: =W9-Q9 -> 0 | Z9: 23.594 | AA9: =Z9-C9 -> -2.4112 | AB9: 23.594 | AC9: 21.594 | AD9: =AC9-AB9 -> -2
A10: Lancer | B10: Lethality | C10: =(H10+D10+E10*F10)*(1+G10)+G10 -> 20.81 | D10: =SUMIFS('Hero Stats'!D:D,'Hero Stats'!A:A,$A$19,'Hero Stats'!B:B,A10,'Hero Stats'!C:C,B10) +SUMIFS('Hero Stats'!D:D,'Hero Stats'!A:A,$A$20,'Hero Stats'!B:B,A10,'Hero Stats'!C:C,B10) +SUMIFS('Hero Stats'!D:D,'Hero Stats'!A:A,$A$21,'Hero Stats'!B:B,A10,'Hero Stats'!C:C,B10) -> 3.23 | E10: 6 | F10: 1 | G10: =C31 -> 0 | H10: 11.58 | J10: 10.045217 | K10: 10.631 | L10: =H10-K10 -> 0.949 | O10: 19.306 | P10: =O10-C10 -> -1.504 | Q10: 19.406 | R10: =Q10-O10 -> 0.1 | T10: 19.406 | U10: =T10-O10 -> 0.1 | W10: 19.406 | X10: =W10-Q10 -> 0 | Z10: 19.406 | AA10: =Z10-C10 -> -1.404 | AB10: 19.406 | AC10: 13.406 | AD10: =AC10-AB10 -> -6
A11: Lancer | B11: Health | C11: =(H11+D11+E11*F11)*(1+G11)+G11 -> 23.96535 | D11: =SUMIFS('Hero Stats'!D:D,'Hero Stats'!A:A,$A$19,'Hero Stats'!B:B,A11,'Hero Stats'!C:C,B11) +SUMIFS('Hero Stats'!D:D,'Hero Stats'!A:A,$A$20,'Hero Stats'!B:B,A11,'Hero Stats'!C:C,B11) +SUMIFS('Hero Stats'!D:D,'Hero Stats'!A:A,$A$21,'Hero Stats'!B:B,A11,'Hero Stats'!C:C,B11) -> 3.23 | E11: 6 | F11: 1 | G11: =C32 -> 0.15 | H11: 11.479 | J11: 10.067 | K11: 10.54 | L11: =H11-K11 -> 0.939 | O11: 19.215 | P11: =O11-C11 -> -4.75035 | Q11: 19.315 | R11: =Q11-O11 -> 0.1 | T11: 19.315 | U11: =T11-O11 -> 0.1 | W11: 19.315 | X11: =W11-Q11 -> 0 | Z11: 19.315 | AA11: =Z11-C11 -> -4.65035 | AB11: 19.315 | AC11: 13.315 | AD11: =AC11-AB11 -> -6
A12: Marksman | B12: Attack | C12: =(H12+D12+E12*F12)*(1+G12)+G12 -> 29.78573 | D12: =SUMIFS('Hero Stats'!D:D,'Hero Stats'!A:A,$A$19,'Hero Stats'!B:B,A12,'Hero Stats'!C:C,B12) +SUMIFS('Hero Stats'!D:D,'Hero Stats'!A:A,$A$20,'Hero Stats'!B:B,A12,'Hero Stats'!C:C,B12) +SUMIFS('Hero Stats'!D:D,'Hero Stats'!A:A,$A$21,'Hero Stats'!B:B,A12,'Hero Stats'!C:C,B12) -> 12.8102 | E12: 2 | F12: 1 | G12: =C33 -> 0.15 | H12: 10.96 | J12: 10.2699 | K12: 10.36 | L12: =H12-K12 -> 0.6 | O12: 23.239 | P12: =O12-C12 -> -6.54673 | Q12: 23.389 | R12: =Q12-O12 -> 0.15 | T12: 23.389 | U12: =T12-O12 -> 0.15 | W12: 23.389 | X12: =W12-Q12 -> 0 | Z12: 23.389 | AA12: =Z12-C12 -> -6.39673 | AB12: 23.389 | AC12: 21.389 | AD12: =AC12-AB12 -> -2
A13: Marksman | B13: Defense | C13: =(H13+D13+E13*F13)*(1+G13)+G13 -> 26.0052 | D13: =SUMIFS('Hero Stats'!D:D,'Hero Stats'!A:A,$A$19,'Hero Stats'!B:B,A13,'Hero Stats'!C:C,B13) +SUMIFS('Hero Stats'!D:D,'Hero Stats'!A:A,$A$20,'Hero Stats'!B:B,A13,'Hero Stats'!C:C,B13) +SUMIFS('Hero Stats'!D:D,'Hero Stats'!A:A,$A$21,'Hero Stats'!B:B,A13,'Hero Stats'!C:C,B13) -> 12.8102 | E13: 2 | F13: 1 | G13: =C34 -> 0 | H13: 11.195 | J13: 10.6249 | K13: 10.625 | L13: =H13-K13 -> 0.57 | O13: 23.504 | P13: =O13-C13 -> -2.5012 | Q13: 23.604 | R13: =Q13-O13 -> 0.1 | T13: 23.604 | U13: =T13-O13 -> 0.1 | W13: 23.604 | X13: =W13-Q13 -> 0 | Z13: 23.604 | AA13: =Z13-C13 -> -2.4012 | AB13: 23.604 | AC13: 21.604 | AD13: =AC13-AB13 -> -2
A14: Marksman | B14: Lethality | C14: =(H14+D14+E14*F14)*(1+G14)+G14 -> 20.585 | D14: =SUMIFS('Hero Stats'!D:D,'Hero Stats'!A:A,$A$19,'Hero Stats'!B:B,A14,'Hero Stats'!C:C,B14) +SUMIFS('Hero Stats'!D:D,'Hero Stats'!A:A,$A$20,'Hero Stats'!B:B,A14,'Hero Stats'!C:C,B14) +SUMIFS('Hero Stats'!D:D,'Hero Stats'!A:A,$A$21,'Hero Stats'!B:B,A14,'Hero Stats'!C:C,B14) -> 3.23 | E14: 6 | F14: 1 | G14: =C35 -> 0 | H14: 11.355 | J14: 10.031304 | K14: 10.56 | L14: =H14-K14 -> 0.795 | O14: 19.235 | P14: =O14-C14 -> -1.35 | Q14: 19.335 | R14: =Q14-O14 -> 0.1 | T14: 19.335 | U14: =T14-O14 -> 0.1 | W14: 19.335 | X14: =W14-Q14 -> 0 | Z14: 19.335 | AA14: =Z14-C14 -> -1.25 | AB14: 19.335 | AC14: 13.335 | AD14: =AC14-AB14 -> -6
A15: Marksman | B15: Health | C15: =(H15+D15+E15*F15)*(1+G15)+G15 -> 23.7227 | D15: =SUMIFS('Hero Stats'!D:D,'Hero Stats'!A:A,$A$19,'Hero Stats'!B:B,A15,'Hero Stats'!C:C,B15) +SUMIFS('Hero Stats'!D:D,'Hero Stats'!A:A,$A$20,'Hero Stats'!B:B,A15,'Hero Stats'!C:C,B15) +SUMIFS('Hero Stats'!D:D,'Hero Stats'!A:A,$A$21,'Hero Stats'!B:B,A15,'Hero Stats'!C:C,B15) -> 3.23 | E15: 6 | F15: 1 | G15: =C36 -> 0.15 | H15: 11.268 | J15: 9.916 | K15: 10.547 | L15: =H15-K15 -> 0.721 | O15: 19.222 | P15: =O15-C15 -> -4.5007 | Q15: 19.322 | R15: =Q15-O15 -> 0.1 | T15: 19.322 | U15: =T15-O15 -> 0.1 | W15: 19.322 | X15: =W15-Q15 -> 0 | Z15: 19.322 | AA15: =Z15-C15 -> -4.4007 | AB15: 19.322 | AC15: 13.322 | AD15: =AC15-AB15 -> -6
A17: Input
A18: Garrison Heroes | B18: Goggle | C18: Belt | D18: Gloves | E18: Boots | G18: =SUMIFS('Hero Stats'!$D:$D,'Hero Stats'!$A:$A,"Gregory",'Hero Stats'!$C:$C,"Attack") +SUMIFS('Hero Stats'!G:G,'Hero Stats'!D:D,$A$20,'Hero Stats'!E:E,D18,'Hero Stats'!F:F,E18) +SUMIFS('Hero Stats'!G:G,'Hero Stats'!D:D,$A$21,'Hero Stats'!E:E,D18,'Hero Stats'!F:F,E18) -> 11.1088 | K18: =K6+D6 -> 13.83 | R18: 1110.88 | S18: 780.62 | T18: =R18-S18 -> 330.26
A19: Eleonora | B19: 0 | C19: 0 | D19: 0 | E19: 0 | G19: =SUMIFS('Hero Stats'!$D:$D,'Hero Stats'!$A:$A,"Gregory",'Hero Stats'!$C:$C,"Attack") +SUMIFS('Hero Stats'!G:G,'Hero Stats'!D:D,$A$20,'Hero Stats'!E:E,D19,'Hero Stats'!F:F,E19) +SUMIFS('Hero Stats'!G:G,'Hero Stats'!D:D,$A$21,'Hero Stats'!E:E,D19,'Hero Stats'!F:F,E19) -> 11.1088 | K19: =K18+E6 -> 19.83 | R19: 1110.88 | S19: 780.62 | T19: =R19-S19 -> 330.26
A20: Lloyd | B20: 0 | C20: 0 | D20: 0 | E20: 0 | R20: 277.5 | S20: 193 | T20: =R20-S20 -> 84.5
A21: Rufus | B21: 0 | C21: 0 | D21: 0 | E21: 0 | R21: 277.5 | S21: 193 | T21: =R21-S21 -> 84.5
D23: Input | F23: Input
A24: Buff Applied | C24: Total | D24: Buffs in use | E24: Widget | F24: Pets in use
A25: Infantry | B25: Attack | C25: =SUM(D25:F25) -> 0.15 | E25: =SUMIFS('Hero Skills'!$H:$H,'Hero Skills'!A:A,$A$19,'Hero Skills'!B:B,"Widget",'Hero Skills'!E:E,A25,'Hero Skills'!F:F,B25,'Hero Skills'!C:C,selfScoutedPosition) +SUMIFS('Hero Skills'!$H:$H,'Hero Skills'!A:A,$A$20,'Hero Skills'!B:B,"Widget",'Hero Skills'!E:E,A25,'Hero Skills'!F:F,B25,'Hero Skills'!C:C,selfScoutedPosition) +SUMIFS('Hero Skills'!$H:$H,'Hero Skills'!A:A,$A$21,'Hero Skills'!B:B,"Widget",'Hero Skills'!E:E,A25,'Hero Skills'!F:F,B25,'Hero Skills'!C:C,selfScoutedPosition) -> 0.15
A26: Infantry | B26: Defense | C26: =SUM(D26:F26) -> 0 | E26: =SUMIFS('Hero Skills'!$H:$H,'Hero Skills'!A:A,$A$19,'Hero Skills'!B:B,"Widget",'Hero Skills'!E:E,A26,'Hero Skills'!F:F,B26,'Hero Skills'!C:C,selfScoutedPosition) +SUMIFS('Hero Skills'!$H:$H,'Hero Skills'!A:A,$A$20,'Hero Skills'!B:B,"Widget",'Hero Skills'!E:E,A26,'Hero Skills'!F:F,B26,'Hero Skills'!C:C,selfScoutedPosition) +SUMIFS('Hero Skills'!$H:$H,'Hero Skills'!A:A,$A$21,'Hero Skills'!B:B,"Widget",'Hero Skills'!E:E,A26,'Hero Skills'!F:F,B26,'Hero Skills'!C:C,selfScoutedPosition) -> 0
A27: Infantry | B27: Lethality | C27: =SUM(D27:F27) -> 0 | E27: =SUMIFS('Hero Skills'!$H:$H,'Hero Skills'!A:A,$A$19,'Hero Skills'!B:B,"Widget",'Hero Skills'!E:E,A27,'Hero Skills'!F:F,B27,'Hero Skills'!C:C,selfScoutedPosition) +SUMIFS('Hero Skills'!$H:$H,'Hero Skills'!A:A,$A$20,'Hero Skills'!B:B,"Widget",'Hero Skills'!E:E,A27,'Hero Skills'!F:F,B27,'Hero Skills'!C:C,selfScoutedPosition) +SUMIFS('Hero Skills'!$H:$H,'Hero Skills'!A:A,$A$21,'Hero Skills'!B:B,"Widget",'Hero Skills'!E:E,A27,'Hero Skills'!F:F,B27,'Hero Skills'!C:C,selfScoutedPosition) -> 0
A28: Infantry | B28: Health | C28: =SUM(D28:F28) -> 0.15 | E28: =SUMIFS('Hero Skills'!$H:$H,'Hero Skills'!A:A,$A$19,'Hero Skills'!B:B,"Widget",'Hero Skills'!E:E,A28,'Hero Skills'!F:F,B28,'Hero Skills'!C:C,selfScoutedPosition) +SUMIFS('Hero Skills'!$H:$H,'Hero Skills'!A:A,$A$20,'Hero Skills'!B:B,"Widget",'Hero Skills'!E:E,A28,'Hero Skills'!F:F,B28,'Hero Skills'!C:C,selfScoutedPosition) +SUMIFS('Hero Skills'!$H:$H,'Hero Skills'!A:A,$A$21,'Hero Skills'!B:B,"Widget",'Hero Skills'!E:E,A28,'Hero Skills'!F:F,B28,'Hero Skills'!C:C,selfScoutedPosition) -> 0.15
A29: Lancer | B29: Attack | C29: =SUM(D29:F29) -> 0.15 | E29: =SUMIFS('Hero Skills'!$H:$H,'Hero Skills'!A:A,$A$19,'Hero Skills'!B:B,"Widget",'Hero Skills'!E:E,A29,'Hero Skills'!F:F,B29,'Hero Skills'!C:C,selfScoutedPosition) +SUMIFS('Hero Skills'!$H:$H,'Hero Skills'!A:A,$A$20,'Hero Skills'!B:B,"Widget",'Hero Skills'!E:E,A29,'Hero Skills'!F:F,B29,'Hero Skills'!C:C,selfScoutedPosition) +SUMIFS('Hero Skills'!$H:$H,'Hero Skills'!A:A,$A$21,'Hero Skills'!B:B,"Widget",'Hero Skills'!E:E,A29,'Hero Skills'!F:F,B29,'Hero Skills'!C:C,selfScoutedPosition) -> 0.15
A30: Lancer | B30: Defense | C30: =SUM(D30:F30) -> 0 | E30: =SUMIFS('Hero Skills'!$H:$H,'Hero Skills'!A:A,$A$19,'Hero Skills'!B:B,"Widget",'Hero Skills'!E:E,A30,'Hero Skills'!F:F,B30,'Hero Skills'!C:C,selfScoutedPosition) +SUMIFS('Hero Skills'!$H:$H,'Hero Skills'!A:A,$A$20,'Hero Skills'!B:B,"Widget",'Hero Skills'!E:E,A30,'Hero Skills'!F:F,B30,'Hero Skills'!C:C,selfScoutedPosition) +SUMIFS('Hero Skills'!$H:$H,'Hero Skills'!A:A,$A$21,'Hero Skills'!B:B,"Widget",'Hero Skills'!E:E,A30,'Hero Skills'!F:F,B30,'Hero Skills'!C:C,selfScoutedPosition) -> 0
A31: Lancer | B31: Lethality | C31: =SUM(D31:F31) -> 0 | E31: =SUMIFS('Hero Skills'!$H:$H,'Hero Skills'!A:A,$A$19,'Hero Skills'!B:B,"Widget",'Hero Skills'!E:E,A31,'Hero Skills'!F:F,B31,'Hero Skills'!C:C,selfScoutedPosition) +SUMIFS('Hero Skills'!$H:$H,'Hero Skills'!A:A,$A$20,'Hero Skills'!B:B,"Widget",'Hero Skills'!E:E,A31,'Hero Skills'!F:F,B31,'Hero Skills'!C:C,selfScoutedPosition) +SUMIFS('Hero Skills'!$H:$H,'Hero Skills'!A:A,$A$21,'Hero Skills'!B:B,"Widget",'Hero Skills'!E:E,A31,'Hero Skills'!F:F,B31,'Hero Skills'!C:C,selfScoutedPosition) -> 0
A32: Lancer | B32: Health | C32: =SUM(D32:F32) -> 0.15 | E32: =SUMIFS('Hero Skills'!$H:$H,'Hero Skills'!A:A,$A$19,'Hero Skills'!B:B,"Widget",'Hero Skills'!E:E,A32,'Hero Skills'!F:F,B32,'Hero Skills'!C:C,selfScoutedPosition) +SUMIFS('Hero Skills'!$H:$H,'Hero Skills'!A:A,$A$20,'Hero Skills'!B:B,"Widget",'Hero Skills'!E:E,A32,'Hero Skills'!F:F,B32,'Hero Skills'!C:C,selfScoutedPosition) +SUMIFS('Hero Skills'!$H:$H,'Hero Skills'!A:A,$A$21,'Hero Skills'!B:B,"Widget",'Hero Skills'!E:E,A32,'Hero Skills'!F:F,B32,'Hero Skills'!C:C,selfScoutedPosition) -> 0.15
A33: Marksman | B33: Attack | C33: =SUM(D33:F33) -> 0.15 | E33: =SUMIFS('Hero Skills'!$H:$H,'Hero Skills'!A:A,$A$19,'Hero Skills'!B:B,"Widget",'Hero Skills'!E:E,A33,'Hero Skills'!F:F,B33,'Hero Skills'!C:C,selfScoutedPosition) +SUMIFS('Hero Skills'!$H:$H,'Hero Skills'!A:A,$A$20,'Hero Skills'!B:B,"Widget",'Hero Skills'!E:E,A33,'Hero Skills'!F:F,B33,'Hero Skills'!C:C,selfScoutedPosition) +SUMIFS('Hero Skills'!$H:$H,'Hero Skills'!A:A,$A$21,'Hero Skills'!B:B,"Widget",'Hero Skills'!E:E,A33,'Hero Skills'!F:F,B33,'Hero Skills'!C:C,selfScoutedPosition) -> 0.15
A34: Marksman | B34: Defense | C34: =SUM(D34:F34) -> 0 | E34: =SUMIFS('Hero Skills'!$H:$H,'Hero Skills'!A:A,$A$19,'Hero Skills'!B:B,"Widget",'Hero Skills'!E:E,A34,'Hero Skills'!F:F,B34,'Hero Skills'!C:C,selfScoutedPosition) +SUMIFS('Hero Skills'!$H:$H,'Hero Skills'!A:A,$A$20,'Hero Skills'!B:B,"Widget",'Hero Skills'!E:E,A34,'Hero Skills'!F:F,B34,'Hero Skills'!C:C,selfScoutedPosition) +SUMIFS('Hero Skills'!$H:$H,'Hero Skills'!A:A,$A$21,'Hero Skills'!B:B,"Widget",'Hero Skills'!E:E,A34,'Hero Skills'!F:F,B34,'Hero Skills'!C:C,selfScoutedPosition) -> 0
A35: Marksman | B35: Lethality | C35: =SUM(D35:F35) -> 0 | E35: =SUMIFS('Hero Skills'!$H:$H,'Hero Skills'!A:A,$A$19,'Hero Skills'!B:B,"Widget",'Hero Skills'!E:E,A35,'Hero Skills'!F:F,B35,'Hero Skills'!C:C,selfScoutedPosition) +SUMIFS('Hero Skills'!$H:$H,'Hero Skills'!A:A,$A$20,'Hero Skills'!B:B,"Widget",'Hero Skills'!E:E,A35,'Hero Skills'!F:F,B35,'Hero Skills'!C:C,selfScoutedPosition) +SUMIFS('Hero Skills'!$H:$H,'Hero Skills'!A:A,$A$21,'Hero Skills'!B:B,"Widget",'Hero Skills'!E:E,A35,'Hero Skills'!F:F,B35,'Hero Skills'!C:C,selfScoutedPosition) -> 0
A36: Marksman | B36: Health | C36: =SUM(D36:F36) -> 0.15 | E36: =SUMIFS('Hero Skills'!$H:$H,'Hero Skills'!A:A,$A$19,'Hero Skills'!B:B,"Widget",'Hero Skills'!E:E,A36,'Hero Skills'!F:F,B36,'Hero Skills'!C:C,selfScoutedPosition) +SUMIFS('Hero Skills'!$H:$H,'Hero Skills'!A:A,$A$20,'Hero Skills'!B:B,"Widget",'Hero Skills'!E:E,A36,'Hero Skills'!F:F,B36,'Hero Skills'!C:C,selfScoutedPosition) +SUMIFS('Hero Skills'!$H:$H,'Hero Skills'!A:A,$A$21,'Hero Skills'!B:B,"Widget",'Hero Skills'!E:E,A36,'Hero Skills'!F:F,B36,'Hero Skills'!C:C,selfScoutedPosition) -> 0.15
D37: 0

Sheet Current Stats - Enemy
A1: Enemy's Base Stats Calculator | L1: Enemy player | M1: General Rooster
C2: Input | L2: Combat Position | M2: Garrison
C3: Scouted Stats | D3: Heroes Effect | E3: Gear | F3: Gear Fudge | G3: Buffs Applied | H3: Base Stats | J3: Mati's Base Stats As At 14-Jun-25 | K3: Difference
A4: Infantry | B4: Attack | C4: 29.78573 | D4: =SUMIFS('Hero Stats'!D:D,'Hero Stats'!A:A,$A$19,'Hero Stats'!B:B,A4,'Hero Stats'!C:C,B4) +SUMIFS('Hero Stats'!D:D,'Hero Stats'!A:A,$A$20,'Hero Stats'!B:B,A4,'Hero Stats'!C:C,B4) +SUMIFS('Hero Stats'!D:D,'Hero Stats'!A:A,$A$21,'Hero Stats'!B:B,A4,'Hero Stats'!C:C,B4) -> 12.8102 | E4: 2 | F4: 1 | G4: =C25 -> 0.15 | H4: =(C4-G4)/(1+G4)-D4-E4*F4 -> 10.96 | J4: 10.3094 | K4: =H4-J4 -> 0.6506
A5: Infantry | B5: Defense | C5: 26.0052 | D5: =SUMIFS('Hero Stats'!D:D,'Hero Stats'!A:A,$A$19,'Hero Stats'!B:B,A5,'Hero Stats'!C:C,B5) +SUMIFS('Hero Stats'!D:D,'Hero Stats'!A:A,$A$20,'Hero Stats'!B:B,A5,'Hero Stats'!C:C,B5) +SUMIFS('Hero Stats'!D:D,'Hero Stats'!A:A,$A$21,'Hero Stats'!B:B,A5,'Hero Stats'!C:C,B5) -> 12.8102 | E5: 2 | F5: 1 | G5: =C26 -> 0 | H5: =(C5-G5)/(1+G5)-D5-E5*F5 -> 11.195 | J5: 10.6344 | K5: =H5-J5 -> 0.5606
A6: Infantry | B6: Lethality | C6: 20.796 | D6: =SUMIFS('Hero Stats'!D:D,'Hero Stats'!A:A,$A$19,'Hero Stats'!B:B,A6,'Hero Stats'!C:C,B6) +SUMIFS('Hero Stats'!D:D,'Hero Stats'!A:A,$A$20,'Hero Stats'!B:B,A6,'Hero Stats'!C:C,B6) +SUMIFS('Hero Stats'!D:D,'Hero Stats'!A:A,$A$21,'Hero Stats'!B:B,A6,'Hero Stats'!C:C,B6) -> 3.23 | E6: 6 | F6: 1 | G6: =C27 -> 0 | H6: =(C6-G6)/(1+G6)-D6-E6*F6 -> 11.566 | J6: 10.167609 | K6: =H6-J6 -> 1.3983913
A7: Infantry | B7: Health | C7: 23.9734 | D7: =SUMIFS('Hero Stats'!D:D,'Hero Stats'!A:A,$A$19,'Hero Stats'!B:B,A7,'Hero Stats'!C:C,B7) +SUMIFS('Hero Stats'!D:D,'Hero Stats'!A:A,$A$20,'Hero Stats'!B:B,A7,'Hero Stats'!C:C,B7) +SUMIFS('Hero Stats'!D:D,'Hero Stats'!A:A,$A$21,'Hero Stats'!B:B,A7,'Hero Stats'!C:C,B7) -> 3.23 | E7: 6 | F7: 1 | G7: =C28 -> 0.15 | H7: =(C7-G7)/(1+G7)-D7-E7*F7 -> 11.486 | J7: 10.101 | K7: =H7-J7 -> 1.385
A8: Lancer | B8: Attack | C8: 29.78573 | D8: =SUMIFS('Hero Stats'!D:D,'Hero Stats'!A:A,$A$19,'Hero Stats'!B:B,A8,'Hero Stats'!C:C,B8) +SUMIFS('Hero Stats'!D:D,'Hero Stats'!A:A,$A$20,'Hero Stats'!B:B,A8,'Hero Stats'!C:C,B8) +SUMIFS('Hero Stats'!D:D,'Hero Stats'!A:A,$A$21,'Hero Stats'!B:B,A8,'Hero Stats'!C:C,B8) -> 12.8102 | E8: 2 | F8: 1 | G8: =C29 -> 0.15 | H8: =(C8-G8)/(1+G8)-D8-E8*F8 -> 10.96 | J8: 10.2594 | K8: =H8-J8 -> 0.7006
A9: Lancer | B9: Defense | C9: 26.0052 | D9: =SUMIFS('Hero Stats'!D:D,'Hero Stats'!A:A,$A$19,'Hero Stats'!B:B,A9,'Hero Stats'!C:C,B9) +SUMIFS('Hero Stats'!D:D,'Hero Stats'!A:A,$A$20,'Hero Stats'!B:B,A9,'Hero Stats'!C:C,B9) +SUMIFS('Hero Stats'!D:D,'Hero Stats'!A:A,$A$21,'Hero Stats'!B:B,A9,'Hero Stats'!C:C,B9) -> 12.8102 | E9: 2 | F9: 1 | G9: =C30 -> 0 | H9: =(C9-G9)/(1+G9)-D9-E9*F9 -> 11.195 | J9: 10.6144 | K9: =H9-J9 -> 0.5806
A10: Lancer | B10: Lethality | C10: 20.81 | D10: =SUMIFS('Hero Stats'!D:D,'Hero Stats'!A:A,$A$19,'Hero Stats'!B:B,A10,'Hero Stats'!C:C,B10) +SUMIFS('Hero Stats'!D:D,'Hero Stats'!A:A,$A$20,'Hero Stats'!B:B,A10,'Hero Stats'!C:C,B10) +SUMIFS('Hero Stats'!D:D,'Hero Stats'!A:A,$A$21,'Hero Stats'!B:B,A10,'Hero Stats'!C:C,B10) -> 3.23 | E10: 6 | F10: 1 | G10: =C31 -> 0 | H10: =(C10-G10)/(1+G10)-D10-E10*F10 -> 11.58 | J10: 10.045217 | K10: =H10-J10 -> 1.5347826
A11: Lancer | B11: Health | C11: 23.96535 | D11: =SUMIFS('Hero Stats'!D:D,'Hero Stats'!A:A,$A$19,'Hero Stats'!B:B,A11,'Hero Stats'!C:C,B11) +SUMIFS('Hero Stats'!D:D,'Hero Stats'!A:A,$A$20,'Hero Stats'!B:B,A11,'Hero Stats'!C:C,B11) +SUMIFS('Hero Stats'!D:D,'Hero Stats'!A:A,$A$21,'Hero Stats'!B:B,A11,'Hero Stats'!C:C,B11) -> 3.23 | E11: 6 | F11: 1 | G11: =C32 -> 0.15 | H11: =(C11-G11)/(1+G11)-D11-E11*F11 -> 11.479 | J11: 10.067 | K11: =H11-J11 -> 1.412 | N11: =RAND() -> 0.76045339
A12: Marksman | B12: Attack | C12: 29.78573 | D12: =SUMIFS('Hero Stats'!D:D,'Hero Stats'!A:A,$A$19,'Hero Stats'!B:B,A12,'Hero Stats'!C:C,B12) +SUMIFS('Hero Stats'!D:D,'Hero Stats'!A:A,$A$20,'Hero Stats'!B:B,A12,'Hero Stats'!C:C,B12) +SUMIFS('Hero Stats'!D:D,'Hero Stats'!A:A,$A$21,'Hero Stats'!B:B,A12,'Hero Stats'!C:C,B12) -> 12.8102 | E12: 2 | F12: 1 | G12: =C33 -> 0.15 | H12: =(C12-G12)/(1+G12)-D12-E12*F12 -> 10.96 | J12: 10.2699 | K12: =H12-J12 -> 0.6901
A13: Marksman | B13: Defense | C13: 26.0052 | D13: =SUMIFS('Hero Stats'!D:D,'Hero Stats'!A:A,$A$19,'Hero Stats'!B:B,A13,'Hero Stats'!C:C,B13) +SUMIFS('Hero Stats'!D:D,'Hero Stats'!A:A,$A$20,'Hero Stats'!B:B,A13,'Hero Stats'!C:C,B13) +SUMIFS('Hero Stats'!D:D,'Hero Stats'!A:A,$A$21,'Hero Stats'!B:B,A13,'Hero Stats'!C:C,B13) -> 12.8102 | E13: 2 | F13: 1 | G13: =C34 -> 0 | H13: =(C13-G13)/(1+G13)-D13-E13*F13 -> 11.195 | J13: 10.6249 | K13: =H13-J13 -> 0.5701
A14: Marksman | B14: Lethality | C14: 20.585 | D14: =SUMIFS('Hero Stats'!D:D,'Hero Stats'!A:A,$A$19,'Hero Stats'!B:B,A14,'Hero Stats'!C:C,B14) +SUMIFS('Hero Stats'!D:D,'Hero Stats'!A:A,$A$20,'Hero Stats'!B:B,A14,'Hero Stats'!C:C,B14) +SUMIFS('Hero Stats'!D:D,'Hero Stats'!A:A,$A$21,'Hero Stats'!B:B,A14,'Hero Stats'!C:C,B14) -> 3.23 | E14: 6 | F14: 1 | G14: =C35 -> 0 | H14: =(C14-G14)/(1+G14)-D14-E14*F14 -> 11.355 | J14: 10.031304 | K14: =H14-J14 -> 1.3236957
A15: Marksman | B15: Health | C15: 23.7227 | D15: =SUMIFS('Hero Stats'!D:D,'Hero Stats'!A:A,$A$19,'Hero Stats'!B:B,A15,'Hero Stats'!C:C,B15) +SUMIFS('Hero Stats'!D:D,'Hero Stats'!A:A,$A$20,'Hero Stats'!B:B,A15,'Hero Stats'!C:C,B15) +SUMIFS('Hero Stats'!D:D,'Hero Stats'!A:A,$A$21,'Hero Stats'!B:B,A15,'Hero Stats'!C:C,B15) -> 3.23 | E15: 6 | F15: 1 | G15: =C36 -> 0.15 | H15: =(C15-G15)/(1+G15)-D15-E15*F15 -> 11.268 | J15: 9.916 | K15: =H15-J15 -> 1.352
A17: Input
A18: Garrison Heroes | B18: Goggle | C18: Belt | D18: Gloves | E18: Boots
A19: Eleonora | B19: 0 | C19: 0 | D19: 0 | E19: 0
A20: Lloyd | B20: 0 | C20: 0 | D20: 0 | E20: 0
A21: Rufus | B21: 0 | C21: 0 | D21: 0 | E21: 0
D23: Input | F23: Input
A24: Buff Applied | C24: Total | D24: Buffs in use | E24: Widget | F24: Pets in use
A25: Infantry | B25: Attack | C25: =SUM(D25:F25) -> 0.15 | E25: =SUMIFS('Hero Skills'!$H:$H,'Hero Skills'!A:A,$A$19,'Hero Skills'!B:B,"Widget",'Hero Skills'!E:E,A25,'Hero Skills'!F:F,B25,'Hero Skills'!C:C,ScoutedPosition) +SUMIFS('Hero Skills'!$H:$H,'Hero Skills'!A:A,$A$20,'Hero Skills'!B:B,"Widget",'Hero Skills'!E:E,A25,'Hero Skills'!F:F,B25,'Hero Skills'!C:C,ScoutedPosition) +SUMIFS('Hero Skills'!$H:$H,'Hero Skills'!A:A,$A$21,'Hero Skills'!B:B,"Widget",'Hero Skills'!E:E,A25,'Hero Skills'!F:F,B25,'Hero Skills'!C:C,ScoutedPosition) -> 0.15
A26: Infantry | B26: Defense | C26: =SUM(D26:F26) -> 0 | E26: =SUMIFS('Hero Skills'!$H:$H,'Hero Skills'!A:A,$A$19,'Hero Skills'!B:B,"Widget",'Hero Skills'!E:E,A26,'Hero Skills'!F:F,B26,'Hero Skills'!C:C,ScoutedPosition) +SUMIFS('Hero Skills'!$H:$H,'Hero Skills'!A:A,$A$20,'Hero Skills'!B:B,"Widget",'Hero Skills'!E:E,A26,'Hero Skills'!F:F,B26,'Hero Skills'!C:C,ScoutedPosition) +SUMIFS('Hero Skills'!$H:$H,'Hero Skills'!A:A,$A$21,'Hero Skills'!B:B,"Widget",'Hero Skills'!E:E,A26,'Hero Skills'!F:F,B26,'Hero Skills'!C:C,ScoutedPosition) -> 0
A27: Infantry | B27: Lethality | C27: =SUM(D27:F27) -> 0 | E27: =SUMIFS('Hero Skills'!$H:$H,'Hero Skills'!A:A,$A$19,'Hero Skills'!B:B,"Widget",'Hero Skills'!E:E,A27,'Hero Skills'!F:F,B27,'Hero Skills'!C:C,ScoutedPosition) +SUMIFS('Hero Skills'!$H:$H,'Hero Skills'!A:A,$A$20,'Hero Skills'!B:B,"Widget",'Hero Skills'!E:E,A27,'Hero Skills'!F:F,B27,'Hero Skills'!C:C,ScoutedPosition) +SUMIFS('Hero Skills'!$H:$H,'Hero Skills'!A:A,$A$21,'Hero Skills'!B:B,"Widget",'Hero Skills'!E:E,A27,'Hero Skills'!F:F,B27,'Hero Skills'!C:C,ScoutedPosition) -> 0 | H27: lko
A28: Infantry | B28: Health | C28: =SUM(D28:F28) -> 0.15 | E28: =SUMIFS('Hero Skills'!$H:$H,'Hero Skills'!A:A,$A$19,'Hero Skills'!B:B,"Widget",'Hero Skills'!E:E,A28,'Hero Skills'!F:F,B28,'Hero Skills'!C:C,ScoutedPosition) +SUMIFS('Hero Skills'!$H:$H,'Hero Skills'!A:A,$A$20,'Hero Skills'!B:B,"Widget",'Hero Skills'!E:E,A28,'Hero Skills'!F:F,B28,'Hero Skills'!C:C,ScoutedPosition) +SUMIFS('Hero Skills'!$H:$H,'Hero Skills'!A:A,$A$21,'Hero Skills'!B:B,"Widget",'Hero Skills'!E:E,A28,'Hero Skills'!F:F,B28,'Hero Skills'!C:C,ScoutedPosition) -> 0.15
A29: Lancer | B29: Attack | C29: =SUM(D29:F29) -> 0.15 | E29: =SUMIFS('Hero Skills'!$H:$H,'Hero Skills'!A:A,$A$19,'Hero Skills'!B:B,"Widget",'Hero Skills'!E:E,A29,'Hero Skills'!F:F,B29,'Hero Skills'!C:C,ScoutedPosition) +SUMIFS('Hero Skills'!$H:$H,'Hero Skills'!A:A,$A$20,'Hero Skills'!B:B,"Widget",'Hero Skills'!E:E,A29,'Hero Skills'!F:F,B29,'Hero Skills'!C:C,ScoutedPosition) +SUMIFS('Hero Skills'!$H:$H,'Hero Skills'!A:A,$A$21,'Hero Skills'!B:B,"Widget",'Hero Skills'!E:E,A29,'Hero Skills'!F:F,B29,'Hero Skills'!C:C,ScoutedPosition) -> 0.15
A30: Lancer | B30: Defense | C30: =SUM(D30:F30) -> 0 | E30: =SUMIFS('Hero Skills'!$H:$H,'Hero Skills'!A:A,$A$19,'Hero Skills'!B:B,"Widget",'Hero Skills'!E:E,A30,'Hero Skills'!F:F,B30,'Hero Skills'!C:C,ScoutedPosition) +SUMIFS('Hero Skills'!$H:$H,'Hero Skills'!A:A,$A$20,'Hero Skills'!B:B,"Widget",'Hero Skills'!E:E,A30,'Hero Skills'!F:F,B30,'Hero Skills'!C:C,ScoutedPosition) +SUMIFS('Hero Skills'!$H:$H,'Hero Skills'!A:A,$A$21,'Hero Skills'!B:B,"Widget",'Hero Skills'!E:E,A30,'Hero Skills'!F:F,B30,'Hero Skills'!C:C,ScoutedPosition) -> 0
A31: Lancer | B31: Lethality | C31: =SUM(D31:F31) -> 0 | E31: =SUMIFS('Hero Skills'!$H:$H,'Hero Skills'!A:A,$A$19,'Hero Skills'!B:B,"Widget",'Hero Skills'!E:E,A31,'Hero Skills'!F:F,B31,'Hero Skills'!C:C,ScoutedPosition) +SUMIFS('Hero Skills'!$H:$H,'Hero Skills'!A:A,$A$20,'Hero Skills'!B:B,"Widget",'Hero Skills'!E:E,A31,'Hero Skills'!F:F,B31,'Hero Skills'!C:C,ScoutedPosition) +SUMIFS('Hero Skills'!$H:$H,'Hero Skills'!A:A,$A$21,'Hero Skills'!B:B,"Widget",'Hero Skills'!E:E,A31,'Hero Skills'!F:F,B31,'Hero Skills'!C:C,ScoutedPosition) -> 0
A32: Lancer | B32: Health | C32: =SUM(D32:F32) -> 0.15 | E32: =SUMIFS('Hero Skills'!$H:$H,'Hero Skills'!A:A,$A$19,'Hero Skills'!B:B,"Widget",'Hero Skills'!E:E,A32,'Hero Skills'!F:F,B32,'Hero Skills'!C:C,ScoutedPosition) +SUMIFS('Hero Skills'!$H:$H,'Hero Skills'!A:A,$A$20,'Hero Skills'!B:B,"Widget",'Hero Skills'!E:E,A32,'Hero Skills'!F:F,B32,'Hero Skills'!C:C,ScoutedPosition) +SUMIFS('Hero Skills'!$H:$H,'Hero Skills'!A:A,$A$21,'Hero Skills'!B:B,"Widget",'Hero Skills'!E:E,A32,'Hero Skills'!F:F,B32,'Hero Skills'!C:C,ScoutedPosition) -> 0.15
A33: Marksman | B33: Attack | C33: =SUM(D33:F33) -> 0.15 | E33: =SUMIFS('Hero Skills'!$H:$H,'Hero Skills'!A:A,$A$19,'Hero Skills'!B:B,"Widget",'Hero Skills'!E:E,A33,'Hero Skills'!F:F,B33,'Hero Skills'!C:C,ScoutedPosition) +SUMIFS('Hero Skills'!$H:$H,'Hero Skills'!A:A,$A$20,'Hero Skills'!B:B,"Widget",'Hero Skills'!E:E,A33,'Hero Skills'!F:F,B33,'Hero Skills'!C:C,ScoutedPosition) +SUMIFS('Hero Skills'!$H:$H,'Hero Skills'!A:A,$A$21,'Hero Skills'!B:B,"Widget",'Hero Skills'!E:E,A33,'Hero Skills'!F:F,B33,'Hero Skills'!C:C,ScoutedPosition) -> 0.15
A34: Marksman | B34: Defense | C34: =SUM(D34:F34) -> 0 | E34: =SUMIFS('Hero Skills'!$H:$H,'Hero Skills'!A:A,$A$19,'Hero Skills'!B:B,"Widget",'Hero Skills'!E:E,A34,'Hero Skills'!F:F,B34,'Hero Skills'!C:C,ScoutedPosition) +SUMIFS('Hero Skills'!$H:$H,'Hero Skills'!A:A,$A$20,'Hero Skills'!B:B,"Widget",'Hero Skills'!E:E,A34,'Hero Skills'!F:F,B34,'Hero Skills'!C:C,ScoutedPosition) +SUMIFS('Hero Skills'!$H:$H,'Hero Skills'!A:A,$A$21,'Hero Skills'!B:B,"Widget",'Hero Skills'!E:E,A34,'Hero Skills'!F:F,B34,'Hero Skills'!C:C,ScoutedPosition) -> 0
A35: Marksman | B35: Lethality | C35: =SUM(D35:F35) -> 0 | E35: =SUMIFS('Hero Skills'!$H:$H,'Hero Skills'!A:A,$A$19,'Hero Skills'!B:B,"Widget",'Hero Skills'!E:E,A35,'Hero Skills'!F:F,B35,'Hero Skills'!C:C,ScoutedPosition) +SUMIFS('Hero Skills'!$H:$H,'Hero Skills'!A:A,$A$20,'Hero Skills'!B:B,"Widget",'Hero Skills'!E:E,A35,'Hero Skills'!F:F,B35,'Hero Skills'!C:C,ScoutedPosition) +SUMIFS('Hero Skills'!$H:$H,'Hero Skills'!A:A,$A$21,'Hero Skills'!B:B,"Widget",'Hero Skills'!E:E,A35,'Hero Skills'!F:F,B35,'Hero Skills'!C:C,ScoutedPosition) -> 0
A36: Marksman | B36: Health | C36: =SUM(D36:F36) -> 0.15 | E36: =SUMIFS('Hero Skills'!$H:$H,'Hero Skills'!A:A,$A$19,'Hero Skills'!B:B,"Widget",'Hero Skills'!E:E,A36,'Hero Skills'!F:F,B36,'Hero Skills'!C:C,ScoutedPosition) +SUMIFS('Hero Skills'!$H:$H,'Hero Skills'!A:A,$A$20,'Hero Skills'!B:B,"Widget",'Hero Skills'!E:E,A36,'Hero Skills'!F:F,B36,'Hero Skills'!C:C,ScoutedPosition) +SUMIFS('Hero Skills'!$H:$H,'Hero Skills'!A:A,$A$21,'Hero Skills'!B:B,"Widget",'Hero Skills'!E:E,A36,'Hero Skills'!F:F,B36,'Hero Skills'!C:C,ScoutedPosition) -> 0.15

Sheet Simulator_Main
D1: My role | E1: ='MAIN PAGE'!B3 -> Garrison | I1: Opponent Role | J1: =IF(E1="Rally","Garrison","Rally") -> Rally
D2: Total Troops | E2: ='MAIN PAGE'!B5 -> 1644203 | I2: Total Troops | J2: ='MAIN PAGE'!N5 -> 1644203
C4: Troop Bonus | D4: Infantry | E4: Lancer | F4: Marksman | I4: Troop Bonus | J4: Infantry | K4: Lancer | L4: Marksman
C5: Attack | D5: =J81 -> 48.914274 | E5: =J85 -> 45.931507 | F5: =J89 -> 48.914274 | I5: Attack | J5: =J96 -> 42.775085 | K5: =J100 -> 42.775085 | L5: =J104 -> 40.159183
C6: Defense | D6: =J82 -> 49.078664 | E6: =J86 -> 35.862098 | F6: =J90 -> 38.184509 | I6: Defense | J6: =J97 -> 31.007859 | K6: =J101 -> 31.007859 | L6: =J105 -> 29.110798
C7: Lethality | D7: =J83 -> 36.447313 | E7: =J87 -> 35.804375 | F7: =J91 -> 36.09125 | I7: Lethality | J7: =J98 -> 27.8483 | K7: =J102 -> 27.8665 | L7: =J106 -> 27.0605
C8: Health | D8: =J84 -> 32.1665 | E8: =J88 -> 31.5635 | F8: =J92 -> 31.8395 | I8: Health | J8: =J99 -> 26.63875 | K8: =J103 -> 26.63 | L8: =J107 -> 25.8725
C9: Damage Dealt | D9: =C34 -> 0.1 | E9: =C40 -> 0 | F9: =C46 -> 0 | I9: Damage Dealt | J9: =J34 -> 0.92390687 | K9: =J40 -> 0 | L9: =J46 -> 0.74900625
C10: Damage Taken | D10: =C35 -> -0.45 | E10: =C41 -> 0.3 | F10: =C47 -> 0 | I10: Damage Taken | J10: =J35 -> -0.8747185 | K10: =J41 -> -0.2 | L10: =J47 -> -0.582395
C12: T11 FC9 Avg | D12: Infantry | E12: Lancer | F12: Marksman | I12: T11 FC9 Avg | J12: Infantry | K12: Lancer | L12: Marksman
C13: Attack | D13: =(1+D5)*'Troop Stats'!B2 -> 898.45693 | E13: =(1+E5)*'Troop Stats'!C2 -> 1267.1507 | F13: =(1+F5)*'Troop Stats'!D2 -> 1397.5997 | I13: Attack | J13: =(1+J5)*'Troop Stats'!B2 -> 787.95153 | K13: =(1+K5)*'Troop Stats'!C2 -> 1181.9273 | L13: =(1+L5)*'Troop Stats'!D2 -> 1152.4571
C14: Defense | D14: =(1+D6)*'Troop Stats'!B3 -> 1352.1239 | E14: =(1+E6)*'Troop Stats'!C3 -> 700.37986 | F14: =(1+F6)*'Troop Stats'!D3 -> 744.50567 | I14: Defense | J14: =(1+J6)*'Troop Stats'!B3 -> 864.21219 | K14: =(1+K6)*'Troop Stats'!C3 -> 608.14932 | L14: =(1+L6)*'Troop Stats'!D3 -> 572.10516
C15: Lethality | D15: =(1+D7)*'Troop Stats'!B4 -> 636.60431 | E15: =(1+E7)*'Troop Stats'!C4 -> 920.10938 | F15: =(1+F7)*'Troop Stats'!D4 -> 964.3725 | I15: Lethality | J15: =(1+J7)*'Troop Stats'!B4 -> 490.4211 | K15: =(1+K7)*'Troop Stats'!C4 -> 721.6625 | L15: =(1+L7)*'Troop Stats'!D4 -> 729.573
C16: Health | D16: =(1+D8)*'Troop Stats'!B5 -> 862.329 | E16: =(1+E8)*'Troop Stats'!C5 -> 586.143 | F16: =(1+F8)*'Troop Stats'!D5 -> 591.111 | I16: Health | J16: =(1+J8)*'Troop Stats'!B5 -> 718.6075 | K16: =(1+K8)*'Troop Stats'!C5 -> 497.34 | L16: =(1+L8)*'Troop Stats'!D5 -> 483.705
C18: Ratio | D18: ='MAIN PAGE'!B8 -> 0.5 | E18: ='MAIN PAGE'!C8 -> 0.1 | F18: ='MAIN PAGE'!D8 -> 0.4 | I18: Ratio | J18: ='MAIN PAGE'!N8 -> 0.5 | K18: ='MAIN PAGE'!O8 -> 0 | L18: ='MAIN PAGE'!P8 -> 0.5
C19: Number of Troops | D19: =D18*$E$2 -> 822101.5 | E19: =E18*$E$2 -> 164420.3 | F19: =F18*$E$2 -> 657681.2 | I19: Number of Troops | J19: =J18*$J$2 -> 822101.5 | K19: =K18*$J$2 -> 0 | L19: =L18*$J$2 -> 822101.5
C21: Single Troop Health | D21: =F9T11_InfantryHealth -> 26 | E21: =F9T11_LancerHealth -> 18 | F21: =F9T11_MarksmanHealth -> 18 | I21: Single Troop Health | J21: =F9T11_InfantryHealth -> 26 | K21: =F9T11_LancerHealth -> 18 | L21: =F9T11_MarksmanHealth -> 18
C23: Troops Survived | D23: =B166 -> #VALUE! | E23: =C166 -> #VALUE! | F23: =D166 -> #VALUE! | I23: Troops Survived | J23: =I166 -> #VALUE! | K23: =J166 -> 0 | L23: =K166 -> #VALUE!
A27: Hero Skill and Widgets Impact
C29: Net Effect | D29: From me | E29: From enemy | H29: From enemy | I29: From me | J29: Net Effect
C30: =SUM(D30:E30) -> 0.653125 | D30: =C64 -> 0.653125 | E30: =U77 -> 0 | F30: Infantry | G30: Attack | H30: =C77 -> 0.4375 | I30: =U64 -> 0 | J30: =SUM(H30:I30) -> 0.4375
C31: =SUM(D31:E31) -> 0.6445 | D31: =D64 -> 0.6445 | E31: =V77 -> 0 | F31: Infantry | G31: Defense | H31: =D77 -> 0.265 | I31: =V64 -> -0.25 | J31: =SUM(H31:I31) -> 0.015
C32: =SUM(D32:E32) -> 0.4375 | D32: =E64 -> 0.4375 | E32: =W77 -> 0 | F32: Infantry | G32: Lethality | H32: =E77 -> 0.25 | I32: =W64 -> -0.2 | J32: =SUM(H32:I32) -> 0.05
C33: =SUM(D33:E33) -> 0.25 | D33: =F64 -> 0.25 | E33: =X77 -> 0 | F33: Infantry | G33: Health | H33: =F77 -> 0 | I33: =X64 -> 0 | J33: =SUM(H33:I33) -> 0
C34: =SUM(D34:E34) -> 0.1 | D34: =G64 -> 0.1 | E34: =Y77 -> 0 | F34: Infantry | G34: Damage Dealt | H34: =G77 -> 0.92390687 | I34: =Y64 -> 0 | J34: =SUM(H34:I34) -> 0.92390687
C35: =SUM(D35:E35) -> -0.45 | D35: =H64 -> -0.7 | E35: =Z77 -> 0.25 | F35: Infantry | G35: Damage Taken | H35: =H77 -> -0.8747185 | I35: =Z64 -> 0 | J35: =SUM(H35:I35) -> -0.8747185
C36: =SUM(D36:E36) -> 0.653125 | D36: =I64 -> 0.653125 | E36: =AA77 -> 0 | F36: Lancer | G36: Attack | H36: =I77 -> 0.4375 | I36: =AA64 -> 0 | J36: =SUM(H36:I36) -> 0.4375
C37: =SUM(D37:E37) -> 0.265 | D37: =J64 -> 0.265 | E37: =AB77 -> 0 | F37: Lancer | G37: Defense | H37: =J77 -> 0.265 | I37: =AB64 -> -0.25 | J37: =SUM(H37:I37) -> 0.015
C38: =SUM(D38:E38) -> 0.4375 | D38: =K64 -> 0.4375 | E38: =AC77 -> 0 | F38: Lancer | G38: Lethality | H38: =K77 -> 0.25 | I38: =AC64 -> -0.2 | J38: =SUM(H38:I38) -> 0.05
C39: =SUM(D39:E39) -> 0.25 | D39: =L64 -> 0.25 | E39: =AD77 -> 0 | F39: Lancer | G39: Health | H39: =L77 -> 0 | I39: =AD64 -> 0 | J39: =SUM(H39:I39) -> 0
C40: =SUM(D40:E40) -> 0 | D40: =M64 -> 0 | E40: =AE77 -> 0 | F40: Lancer | G40: Damage Dealt | H40: =M77 -> 0 | I40: =AE64 -> 0 | J40: =SUM(H40:I40) -> 0
C41: =SUM(D41:E41) -> 0.3 | D41: =N64 -> 0 | E41: =AF77 -> 0.3 | F41: Lancer | G41: Damage Taken | H41: =N77 -> -0.2 | I41: =AF64 -> 0 | J41: =SUM(H41:I41) -> -0.2
C42: =SUM(D42:E42) -> 0.653125 | D42: =O64 -> 0.653125 | E42: =AG77 -> 0 | F42: Marksman | G42: Attack | H42: =O77 -> 0.4375 | I42: =AG64 -> 0 | J42: =SUM(H42:I42) -> 0.4375
C43: =SUM(D43:E43) -> 0.265 | D43: =P64 -> 0.265 | E43: =AH77 -> 0 | F43: Marksman | G43: Defense | H43: =P77 -> 0.265 | I43: =AH64 -> -0.25 | J43: =SUM(H43:I43) -> 0.015
C44: =SUM(D44:E44) -> 0.4375 | D44: =Q64 -> 0.4375 | E44: =AI77 -> 0 | F44: Marksman | G44: Lethality | H44: =Q77 -> 0.25 | I44: =AI64 -> -0.2 | J44: =SUM(H44:I44) -> 0.05
C45: =SUM(D45:E45) -> 0.25 | D45: =R64 -> 0.25 | E45: =AJ77 -> 0 | F45: Marksman | G45: Health | H45: =R77 -> 0 | I45: =AJ64 -> 0 | J45: =SUM(H45:I45) -> 0
C46: =SUM(D46:E46) -> 0 | D46: =S64 -> 0 | E46: =AK77 -> 0 | F46: Marksman | G46: Damage Dealt | H46: =S77 -> 0.74900625 | I46: =AK64 -> 0 | J46: =SUM(H46:I46) -> 0.74900625
C47: =SUM(D47:E47) -> 0 | D47: =T64 -> 0 | E47: =AL77 -> 0 | F47: Marksman | G47: Damage Taken | H47: =T77 -> -0.582395 | I47: =AL64 -> 0 | J47: =SUM(H47:I47) -> -0.582395
A52: My troops
A53: Hero Position | B53: Name | C53: Friend Effect | U53: Enemy Effect
...

Sheet Game Data -->

Sheet Hero Profile
A1: Photo | B1: Name | C1: Type | D1: Notes | E1: Generation
B2: Elif | C2: Infantry | E2: 14
B3: Dominic | C3: Lancer | E3: 14
B4: Cara | C4: Marksman | E4: 14
B5: Gisela | C5: Infantry | E5: 13
B6: Flora | C6: Lancer | E6: 13
B7: Vulcanus | C7: Marksman | E7: 13
B8: Hervor | C8: Infantry | E8: 12
B9: Karol | C9: Lancer | E9: 12
B10: Ligeia | C10: Marksman | E10: 12
B11: Eleonora | C11: Infantry | E11: 11
B12: Lloyd | C12: Lancer | E12: 11
B13: Rufus | C13: Marksman | E13: 11
B14: Gregory | C14: Infantry | E14: 10
B15: Freya | C15: Lancer | E15: 10
B16: Blanchette | C16: Marksman | E16: 10
B17: Magnus | C17: Infantry | E17: 9
B18: Fred | C18: Lancer | E18: 9
B19: Xura | C19: Marksman | E19: 9
B20: Gatot | C20: Infantry | E20: 8
B21: Sonya | C21: Lancer | E21: 8
B22: Hendrik | C22: Marksman | E22: 8
... B52: Sergey | C52: Infantry | E52: SR

Sheet Hero Stats
A1: Name | B1: Troop Type | C1: Attribute | D1: Value
A2: Hank | B2: Infantry | C2: Attack | D2: 19.6156
A3: Hank | B3: Infantry | C3: Defense | D3: 19.6156
A4: Hank | B4: Infantry | C4: Lethality | D4: 4.9
A5: Hank | B5: Infantry | C5: Health | D5: 4.9
A6: Estrella | B6: Lancer | C6: Attack | D6: 19.6156
A7: Estrella | B7: Lancer | C7: Defense | D7: 19.6156
A8: Estrella | B8: Lancer | C8: Lethality | D8: 4.9
A9: Estrella | B9: Lancer | C9: Health | D9: 4.9
A10: Viveca | B10: Marksman | C10: Attack | D10: 19.6156
A11: Viveca | B11: Marksman | C11: Defense | D11: 19.6156
A12: Viveca | B12: Marksman | C12: Lethality | D12: 4.9
A13: Viveca | B13: Marksman | C13: Health | D13: 4.9
... A185: Jeronimo | B185: Infantry | C185: Health | D185: 0.625

Sheet Hero Skills
A1: Name | B1: Skill source | C1: Rally/Garrison/All | D1: Affecting Side | E1: Troop Type | F1: Attribute | G1: Specific Target | H1: Average Amount % | I1: Skill Type | J1: Probability | K1: Amount when hit | L1: Frequency of ocurrence | M1: Trigger Turns or Attacks or Strikes or Received | N1: Number of turns when occured | O1: Effect Turns or Attacks | P1: Damage Category | Q1: Multiplier | R1: Skill category
A2: Elif | B2: Skill 1 | C2: All | D2: Foe | E2: Infantry | F2: Attack | H2: -0.25 | I2: Stats-based | P2: Both | R2: =IF(OR(F2="Attack",F2="Crit Rate",F2="Lethality"),"Offensive", IF(OR(F2="Defense",F2="Health"),"Defensive",F2)) -> Offensive
A3: Elif | B3: Skill 1 | C3: All | D3: Foe | E3: Lancer | F3: Attack | H3: -0.25 | I3: Stats-based | P3: Both | R3: =IF(OR(F3="Attack",F3="Crit Rate",F3="Lethality"),"Offensive", IF(OR(F3="Defense",F3="Health"),"Defensive",F3)) -> Offensive
A4: Elif | B4: Skill 1 | C4: All | D4: Foe | E4: Marksman | F4: Attack | H4: -0.25 | I4: Stats-based | P4: Both | R4: =IF(OR(F4="Attack",F4="Crit Rate",F4="Lethality"),"Offensive", IF(OR(F4="Defense",F4="Health"),"Defensive",F4)) -> Offensive
A5: Elif | B5: Skill 2 | C5: All | D5: Friend | E5: Infantry | F5: Attack | H5: 0.15 | I5: Stats-based | P5: Both | R5: =IF(OR(F5="Attack",F5="Crit Rate",F5="Lethality"),"Offensive", IF(OR(F5="Defense",F5="Health"),"Defensive",F5)) -> Offensive
A6: Elif | B6: Skill 2 | C6: All | D6: Friend | E6: Lancer | F6: Attack | H6: 0.15 | I6: Stats-based | P6: Both | R6: =IF(OR(F6="Attack",F6="Crit Rate",F6="Lethality"),"Offensive", IF(OR(F6="Defense",F6="Health"),"Defensive",F6)) -> Offensive
A7: Elif | B7: Skill 2 | C7: All | D7: Friend | E7: Marksman | F7: Attack | H7: 0.15 | I7: Stats-based | P7: Both | R7: =IF(OR(F7="Attack",F7="Crit Rate",F7="Lethality"),"Offensive", IF(OR(F7="Defense",F7="Health"),"Defensive",F7)) -> Offensive
A8: Elif | B8: Skill 2 | C8: All | D8: Friend | E8: Infantry | F8: Defense | H8: 0.1 | I8: Stats-based | P8: Both | R8: =IF(OR(F8="Attack",F8="Crit Rate",F8="Lethality"),"Offensive", IF(OR(F8="Defense",F8="Health"),"Defensive",F8)) -> Defensive
A9: Elif | B9: Skill 2 | C9: All | D9: Friend | E9: Lancer | F9: Defense | H9: 0.1 | I9: Stats-based | P9: Both | R9: =IF(OR(F9="Attack",F9="Crit Rate",F9="Lethality"),"Offensive", IF(OR(F9="Defense",F9="Health"),"Defensive",F9)) -> Defensive
A10: Elif | B10: Skill 2 | C10: All | D10: Friend | E10: Marksman | F10: Defense | H10: 0.1 | I10: Stats-based | P10: Both | R10: =IF(OR(F10="Attack",F10="Crit Rate",F10="Lethality"),"Offensive", IF(OR(F10="Defense",F10="Health"),"Defensive",F10)) -> Defensive
